from datetime import datetime, timedelta, UTC
from typing import Optional
from jose import JWTError, jwt
from passlib.context import CryptContext
from fastapi import Depends, HTTPException, status
from fastapi.security import OAuth2PasswordBearer
from sqlalchemy.orm import Session
import os
from dotenv import load_dotenv
from http import HTTPStatus
from api.database import get_db
from api import models, schemas

load_dotenv()

SECRET_KEY = os.getenv("SECRET_KEY")
ALGORITHM = os.getenv("ALGORITHM")
ACCESS_TOKEN_EXPIRE_MINUTES = int(os.getenv("ACCESS_TOKEN_EXPIRE_MINUTES"))

pwd_context = CryptContext(schemes=["bcrypt"], deprecated="auto")
oauth2_scheme = OAuth2PasswordBearer(tokenUrl="token")

def verify_password(plain_password: str, hashed_password: str) -> bool:
    return pwd_context.verify(plain_password, hashed_password)

def get_password_hash(password: str) -> str:
    return pwd_context.hash(password)

def create_access_token(data: dict, expires_delta: Optional[timedelta] = None):
    to_encode = data.copy()
    if expires_delta:
        expire = datetime.now(UTC) + expires_delta
    else:
        expire = datetime.now(UTC) + timedelta(minutes=15)
    to_encode.update({"exp": expire})
    encoded_jwt = jwt.encode(to_encode, SECRET_KEY, algorithm=ALGORITHM)
    return encoded_jwt

async def get_current_user(
    db: Session = Depends(get_db),
    token: str = Depends(oauth2_scheme)
):
    credentials_exception = HTTPException(
        status_code=HTTPStatus.UNAUTHORIZED,
        detail="Could not validate credentials",
        headers={"WWW-Authenticate": "Bearer"},
    )

    try:
        payload = jwt.decode(token, SECRET_KEY, algorithms=[ALGORITHM])
        username: str = payload.get("sub")
        if username is None:
            raise credentials_exception
        token_data = schemas.TokenData(username=username)
    except JWTError:
        raise credentials_exception

    user = db.query(models.User).filter(models.User.email == token_data.username).first()
    if user is None:
        raise credentials_exception
    return user